Workbook

Sheet Balance Sheet
B1: The Tata Power Company | J1: Balance Sheet | P1: Common Sizing Balance Sheet | V1: Horizontal Analysis Balance Sheet
B2: Consolidated Balance Sheet | C2: ----------in Rs Cr.-----------
C3: 45741 | D3: 45740 | E3: 45739 | F3: 45738 | G3: 45737 | L3: In Rs. Cr. | R3: In Rs. Cr. | X3: In Rs. Cr.
C4: 12 mths | D4: 12 mths | E4: 12 mths | F4: 12 mths | G4: 12 mths | L4: 45741 | M4: 45740 | N4: 45739 | R4: 45741 | S4: 45740 | T4: 45739 | X4: 45741 | Y4: 45740 | Z4: 45739
J5: EQUITY AND LIABILITIES: | P5: EQUITIES AND LIABILITIES: | V5: EQUITIES AND LIABILITIES:
B6: EQUITIES AND LIABILITIES | J6: Equity share capital | L6: 319.56 | M6: 319.56 | N6: 319.56 | P6: Equity share capital | R6: =L6/L48 -> 0.0020393244 | S6: =M6/M48 -> 0.0022900575 | T6: =N6/N48 -> 0.0024899973 | V6: Equity share capital | X6: =(L6-M6)/M6 -> 0 | Y6: =(M6-N6)/N6 -> 0
B7: SHAREHOLDER'S FUNDS | J7: Other equity (reserves and surplus) | L7: 35521.11 | M7: 32035.73 | N7: 28467.87 | P7: Other equity (reserves and surplus) | R7: =L7/L48 -> 0.22668378 | S7: =M7/M48 -> 0.22957711 | T7: =N7/N48 -> 0.22182037 | V7: Other equity (reserves and surplus) | X7: =(L7-M7)/M7 -> 0.10879665 | Y7: =(M7-N7)/N7 -> 0.12532936
B8: Equity Share Capital | C8: 319.56 | D8: 319.56 | E8: 319.56 | F8: 319.56 | G8: 319.56 | J8: Total Shareholders funds | L8: =(L6+L7) -> 35840.67 | M8: =(M6+M7) -> 32355.29 | N8: =(N6+N7) -> 28787.43 | P8: Total Shareholders funds | R8: =L8/L48 -> 0.2287231 | S8: =M8/M48 -> 0.23186717 | T8: =N8/N48 -> 0.22431037 | V8: Total Shareholders funds | X8: =(L8-M8)/M8 -> 0.10772211 | Y8: =(M8-N8)/N8 -> 0.12393812
B9: Total Share Capital | C9: 319.56 | D9: 319.56 | E9: 319.56 | F9: 319.56 | G9: 319.56
B10: Reserves and Surplus | C10: 35521.11 | D10: 32035.73 | E10: 28467.87 | F10: 22122 | G10: 20502.7 | J10: NON-CURRENT LIABILITIES: | P10: NON-CURRENT LIABILITIES: | V10: NON-CURRENT LIABILITIES:
B11: Total Reserves and Surplus | C11: 35521.11 | D11: 32035.73 | E11: 28467.87 | F11: 22122 | G11: 20502.7 | J11: Long term borrowings | L11: 44129.72 | M11: 37392.25 | N11: 30708.49 | P11: Long term borrowings | R11: =L11/L48 -> 0.28162103 | S11: =M11/M48 -> 0.26796345 | T11: =N11/N48 -> 0.23927918 | V11: Long term borrowings | X11: =(L11-M11)/M11 -> 0.18018359 | Y11: =(M11-N11)/N11 -> 0.21765186
B12: Total Shareholders Funds | C12: 35840.67 | D12: 32355.29 | E12: 28787.43 | F12: 22441.56 | G12: 20822.26 | J12: Deferred Tax liabilities | L12: 4104.12 | M12: 2772.33 | N12: 1919.37 | P12: Deferred Tax liabilities | R12: =L12/L48 -> 0.026191114 | S12: =M12/M48 -> 0.019867302 | T12: =N12/N48 -> 0.014955645 | V12: Deferred Tax liabilities | X12: =(L12-M12)/M12 -> 0.48038653 | Y12: =(M12-N12)/N12 -> 0.44439582
B13: Hybrid/Debt/Other Securities | C13: 0 | D13: 0 | E13: 0 | F13: 0 | G13: 1500 | J13: Other long term liabilities | L13: 17800.9 | M13: 17223.11 | N13: 14768.92 | P13: Other long term liabilities | R13: =L13/L48 -> 0.11359936 | S13: =M13/M48 -> 0.12342568 | T13: =N13/N48 -> 0.11507877 | V13: Other long term liabilities | X13: =(L13-M13)/M13 -> 0.033547367 | Y13: =(M13-N13)/N13 -> 0.16617261
B14: Minority Interest | C14: 6765.37 | D14: 5977.48 | E14: 5416.69 | F14: 3586.9 | G14: 2927.3 | J14: Long term provisions | L14: 2548.69 | M14: 1865.08 | N14: 1420.02 | P14: Long term provisions | R14: =L14/L48 -> 0.016264882 | S14: =M14/M48 -> 0.013365691 | T14: =N14/N48 -> 0.011064733 | V14: Long term provisions | X14: =(L14-M14)/M14 -> 0.36653119 | Y14: =(M14-N14)/N14 -> 0.31341812
B15: NON-CURRENT LIABILITIES | J15: Total Non-Current Liabilities | L15: 68583.43 | M15: 59252.77 | N15: 48816.8 | P15: Total Non-Current Liabilities | R15: =L15/L48 -> 0.43767639 | S15: =M15/M48 -> 0.42462213 | T15: =N15/N48 -> 0.38037833 | V15: Total Non-Current Liabilities | X15: =(L15-M15)/M15 -> 0.15747213 | Y15: =(M15-N15)/N15 -> 0.21377825
B16: Long Term Borrowings | C16: 44129.72 | D16: 37392.25 | E16: 30708.49 | F16: 32729.7 | G16: 30045.03
B17: Deferred Tax Liabilities [Net] | C17: 4104.12 | D17: 2772.33 | E17: 1919.37 | F17: 1033.3 | G17: 976.15 | J17: CURRENT LIABILITIES: | P17: CURRENT LIABILITIES: | V17: CURRENT LIABILITIES:
B18: Other Long Term Liabilities | C18: 17800.9 | D18: 17223.11 | E18: 14768.92 | F18: 12506.67 | G18: 10771.81 | J18: Short-term borrowings | L18: 14015.84 | M18: 12087.56 | N18: 18265.94 | P18: Short-term borrowings | R18: =L18/L48 -> 0.089444377 | S18: =M18/M48 -> 0.086622878 | T18: =N18/N48 -> 0.14232739 | V18: Short-term borrowings | X18: =(L18-M18)/M18 -> 0.15952599 | Y18: =(M18-N18)/N18 -> -0.33824594
B19: Long Term Provisions | C19: 2548.69 | D19: 1865.08 | E19: 1420.02 | F19: 1218.18 | G19: 839.58 | J19: Trade Payables | L19: 8854.55 | M19: 9321.37 | N19: 7407.2 | P19: Trade Payables | R19: =L19/L48 -> 0.05650676 | S19: =M19/M48 -> 0.066799577 | T19: =N19/N48 -> 0.057716572 | V19: Trade Payables | X19: =(L19-M19)/M19 -> -0.050080621 | Y19: =(M19-N19)/N19 -> 0.25842019
B20: Total Non-Current Liabilities | C20: 68583.43 | D20: 59252.77 | E20: 48816.8 | F20: 47487.85 | G20: 42632.57 | J20: Other current liabilities | L20: 22213.87 | M20: 20264.68 | N20: 19343.91 | P20: Other current liabilities | R20: =L20/L48 -> 0.14176145 | S20: =M20/M48 -> 0.14522244 | T20: =N20/N48 -> 0.15072688 | V20: Other current liabilities | X20: =(L20-M20)/M20 -> 0.096186567 | Y20: =(M20-N20)/N20 -> 0.047599994
B21: CURRENT LIABILITIES | J21: Short term provisions | L21: 437.56 | M21: 294.34 | N21: 311.07 | P21: Short term provisions | R21: =L21/L48 -> 0.0027923608 | S21: =M21/M48 -> 0.0021093238 | T21: =N21/N48 -> 0.0024238436 | V21: Short term provisions | X21: =(L21-M21)/M21 -> 0.48658015 | Y21: =(M21-N21)/N21 -> -0.053782107
B22: Short Term Borrowings | C22: 14015.84 | D22: 12087.56 | E22: 18265.94 | F22: 14860.3 | G22: 8436.21 | J22: Total Current Liabilities | L22: 45521.82 | M22: 41967.95 | N22: 45328.12 | P22: Total Current Liabilities | R22: =L22/L48 -> 0.29050495 | S22: =M22/M48 -> 0.30075422 | T22: =N22/N48 -> 0.35319469 | V22: Total Current Liabilities | X22: =(L22-M22)/M22 -> 0.084680572 | Y22: =(M22-N22)/N22 -> -0.074129922
B23: Trade Payables | C23: 8854.55 | D23: 9321.37 | E23: 7407.2 | F23: 10459.6 | G23: 7120.08
B24: Other Current Liabilities | C24: 22213.87 | D24: 20264.68 | E24: 19343.91 | F24: 13703.56 | G24: 15142.7 | J24: Total Liabilities and shareholders equity | L24: =L8+L15+L22 -> 149945.92 | M24: =M8+M15+M22 -> 133576.01 | N24: =N8+N15+N22 -> 122932.35 | P24: Total Liabilities and shareholders equity | R24: =L24/L48 -> 0.95690443 | S24: =M24/M48 -> 0.95724352 | T24: =N24/N48 -> 0.95788339 | V24: Total Liabilities and shareholders equity | X24: =(L24-M24)/M24 -> 0.12255127 | Y24: =(M24-N24)/N24 -> 0.086581441
B25: Short Term Provisions | C25: 437.56 | D25: 294.34 | E25: 311.07 | F25: 344.82 | G25: 270.11
B26: Total Current Liabilities | C26: 45521.82 | D26: 41967.95 | E26: 45328.12 | F26: 39368.28 | G26: 30969.1 | J26: ASSETS: | P26: ASSETS: | V26: ASSETS:
B27: Total Capital And Liabilities | C27: 1,56,711.29 | D27: 1,39,553.49 | E27: 1,28,349.04 | F27: 1,12,884.59 | G27: 98851.23 | J27: NON-CURRENT ASSETS | P27: NON-CURRENT ASSETS | V27: NON-CURRENT ASSETS
B28: ASSETS | J28: Net PPE (tangible assets) | L28: 75351.27 | M28: 63992.81 | N28: 58507.01 | P28: Net PPE (tangible assets) | R28: =L28/L48 -> 0.48086646 | S28: =M28/M48 -> 0.4585906 | T28: =N28/N48 -> 0.45588401 | V28: Net PPE (tangible assets) | X28: =(L28-M28)/M28 -> 0.17749588 | Y28: =(M28-N28)/N28 -> 0.093763123
B29: NON-CURRENT ASSETS | J29: Intangible assets | L29: 1371.7 | M29: 1459.29 | N29: 1381.34 | P29: Intangible assets | R29: =L29/L48 -> 0.0087537281 | S29: =M29/M48 -> 0.010457685 | T29: =N29/N48 -> 0.01076334 | V29: Intangible assets | X29: =(L29-M29)/M29 -> -0.06002234 | Y29: =(M29-N29)/N29 -> 0.056430712
B30: Net PPE(Tangible Assets) | C30: 75351.27 | D30: 63992.81 | E30: 58507.01 | F30: 54164.95 | G30: 48748.86 | J30: Capital Work in Progress | L30: 12678.87 | M30: 11561.31 | N30: 5376.36 | P30: Capital Work in Progress | R30: =L30/L48 -> 0.080912284 | S30: =M30/M48 -> 0.082851622 | T30: =N30/N48 -> 0.041892357 | V30: Capital Work in Progress | X30: =(L30-M30)/M30 -> 0.096663786 | Y30: =(M30-N30)/N30 -> 1.1503973
B31: Intangible Assets | C31: 1371.7 | D31: 1459.29 | E31: 1381.34 | F31: 1366.18 | G31: 1345.85
B32: Capital Work-In-Progress | C32: 12678.87 | D32: 11561.31 | E32: 5376.36 | F32: 4635.1 | G32: 3599.8 | J32: Total fixed assets | L32: 89401.84 | M32: 77013.41 | N32: 65264.71 | P32: Total fixed assets | R32: =L32/L48 -> 0.57053248 | S32: =M32/M48 -> 0.55189991 | T32: =N32/N48 -> 0.50853971 | V32: Total fixed assets | X32: =(L32-M32)/M32 -> 0.16086069 | Y32: =(M32-N32)/N32 -> 0.18001612
B33: Fixed Assets | C33: 89401.84 | D33: 77013.41 | E33: 65264.71 | F33: 60166.23 | G33: 53694.51 | J33: Non-Current investments | L33: 15013.97 | M33: 14838.1 | N33: 15520.09 | P33: Non-Current investments | R33: =L33/L48 -> 0.095814107 | S33: =M33/M48 -> 0.10633403 | T33: =N33/N48 -> 0.12093185 | V33: Non-Current investments | X33: =(L33-M33)/M33 -> 0.011852596 | Y33: =(M33-N33)/N33 -> -0.0439424
B34: Non-Current Investments | C34: 15013.97 | D34: 14838.1 | E34: 15520.09 | F34: 13749.81 | G34: 12649.51 | J34: Deferred Tax assets | L34: 517.99 | M34: 499.09 | N34: 252.9 | P34: Deferred Tax assets | R34: =L34/L48 -> 0.003305638 | S34: =M34/M48 -> 0.0035766203 | T34: =N34/N48 -> 0.0019705855 | V34: Deferred Tax assets | X34: =(L34-M34)/M34 -> 0.037868921 | Y34: =(M34-N34)/N34 -> 0.97346777
B35: Deferred Tax Assets [Net] | C35: 517.99 | D35: 499.09 | E35: 252.9 | F35: 334.6 | G35: 184.02
B36: Long Term Loans And Advances | C36: 2 | D36: 2.48 | E36: 2.99 | F36: 3.45 | G36: 58.14 | J36: Other non-current Assets | L36: 13058.56 | M36: 8678.91 | N36: 5925.04 | P36: Other non-current Assets | R36: =L36/L48 -> 0.083335338 | S36: =M36/M48 -> 0.062195527 | T36: =N36/N48 -> 0.046167648 | V36: Other non-current Assets | X36: =(L36-M36)/M36 -> 0.50463134 | Y36: =(M36-N36)/N36 -> 0.46478505
B37: Other Non-Current Assets | C37: 13058.56 | D37: 8678.91 | E37: 5925.04 | F37: 5329.36 | G37: 4573.77 | J37: Total Non-Current Assets | L37: 119645.82 | M37: 102789.45 | N37: 88824.04 | P37: Total Non-Current Assets | R37: =L37/L48 -> 0.76353939 | S37: =M37/M48 -> 0.73661831 | T37: =N37/N48 -> 0.69211296 | V37: Total Non-Current Assets | X37: =(L37-M37)/M37 -> 0.1639893 | Y37: 0.4332
B38: Total Non-Current Assets | C38: 1,19,645.82 | D38: 1,02,789.45 | E38: 88824.04 | F38: 81441.76 | G38: 72954.52
B39: CURRENT ASSETS | J39: CURRENT ASSETS | P39: CURRENT ASSETS | V39: CURRENT ASSETS
B40: Current Investments | C40: 1302.42 | D40: 1477.89 | E40: 1149.6 | F40: 410.52 | G40: 499.54 | J40: Current Investments | L40: 1302.42 | M40: 1477.89 | N40: 1149.6 | P40: Current Investments | R40: =L40/L48 -> 0.0083116064 | S40: =M40/M48 -> 0.010590978 | T40: =N40/N48 -> 0.0089576319 | V40: Current Investments | X40: =(L40-M40)/M40 -> -0.11873008 | Y40: =(M40-N40)/N40 -> 0.28556889
...

Sheet Income Statement
B1: The Tata Power Company | J1: Income Statement | O1: Income Statement Common Sizing on Total Revenue | T1: Income Statement Horizontal Analysis
B3: Consolidated Profit & Loss account | C3: ---------------in Rs. Cr.-------------- | K3: In Rs. Cr. | P3: In Rs. Cr. | U3: In Rs. Cr.
C4: 45741 | D4: 45740 | E4: 45739 | F4: 45738 | G4: 45737 | K4: 45741 | L4: 45740 | M4: 45739 | P4: 45741 | Q4: 45740 | R4: 45739 | U4: 45741 | V4: 45740 | W4: 45739
C5: 12 mths | D5: 12 mths | E5: 12 mths | F5: 12 mths | G5: 12 mths | J5: Total Revenue | K5: =C13 -> 66992.17 | L5: =D13 -> 63272.32 | M5: =E13 -> 56547.1 | O5: Total Revenue | P5: 1 | Q5: 1 | R5: 1 | T5: Total Revenue | U5: =(K5-L5)/L5 -> 0.058791111 | V5: =(L5-M5)/M5 -> 0.1189313
J6: Cost of Goods Sold | K6: =(C15+C16+C17+C18+C20) -> 38954.62 | L6: =(D15+D16+D17+D18+D20) -> 39572.9 | M6: =(E15+E16+E17+E18+E20) -> 36808.24 | O6: Cost of Goods Sold | P6: =K6/$K$5 -> 0.58148019 | Q6: =L6/L5 -> 0.62543779 | R6: =M6/M5 -> 0.65093064 | T6: Cost of Goods Sold | U6: =(K6-L6)/L6 -> -0.015623823 | V6: =(L6-M6)/M6 -> 0.075109812
B7: INCOME
B8: Revenue From Operations [Gross] | C8: 63618.07 | D8: 59887.92 | E8: 53623.89 | F8: 41461.68 | G8: 31596.3 | J8: Gross Profit | K8: =(K5-K6) -> 28037.55 | L8: =(L5-L6) -> 23699.42 | M8: =(M5-M6) -> 19738.86 | O8: Gross Profit | P8: =K8/K5 -> 0.41851981 | Q8: =L8/L5 -> 0.37456221 | R8: =M8/M5 -> 0.34906936 | T8: Gross Profit | U8: =(K8-L8)/L8 -> 0.18304794 | V8: =(L8-M8)/M8 -> 0.20064786
B9: Revenue From Operations [Net] | C9: 63618.07 | D9: 59887.92 | E9: 53623.89 | F9: 41461.68 | G9: 31596.3
B10: Other Operating Revenues | C10: 1860.17 | D10: 1560.98 | E10: 1485.19 | F10: 1353.99 | G10: 871.8 | J10: Operating Expenses: | K10: =(C19+C21+C24) -> 12593.75 | L10: =(D19+D21+D24) -> 11092.17 | M10: =(E19+E21+E24) -> 10594.52 | O10: Operating Expenses: | P10: =K10/K5 -> 0.18798839 | Q10: =L10/L5 -> 0.17530841 | R10: =M10/M5 -> 0.18735744 | T10: Operating Expenses: | U10: =(K10-L10)/L10 -> 0.13537297 | V10: =(L10-M10)/M10 -> 0.046972397
B11: Total Operating Revenues | C11: 65478.24 | D11: 61448.9 | E11: 55109.08 | F11: 42815.67 | G11: 32468.1
B12: Other Income | C12: 1513.93 | D12: 1823.42 | E12: 1438.02 | F12: 919.96 | G12: 439.24 | J12: EBITDA | K12: =(K8-K10) -> 15443.8 | L12: =(L8-L10) -> 12607.25 | M12: =(M8-M10) -> 9144.34 | O12: EBITDA | P12: =K12/K5 -> 0.23053142 | Q12: =L12/L5 -> 0.1992538 | R12: =M12/M5 -> 0.16171192 | T12: EBITDA | U12: =(K12-L12)/L12 -> 0.22499356 | V12: =(L12-M12)/M12 -> 0.37869436
B13: Total Revenue | C13: 66992.17 | D13: 63272.32 | E13: 56547.1 | F13: 43735.63 | G13: 32907.34
B14: EXPENSES | J14: Depreciation and Amortization | K14: =C23 -> 4116.86 | L14: =D23 -> 3786.37 | M14: =E23 -> 3439.2 | O14: Depreciation and Amortization | P14: =K14/K5 -> 0.061452853 | Q14: =L14/L5 -> 0.05984244 | R14: =M14/M5 -> 0.060820095 | T14: Depreciation and Amortization | U14: =(K14-L14)/L14 -> 0.087284127 | V14: =(L14-M14)/M14 -> 0.10094499
B15: Cost Of Materials Consumed | C15: 4921.46 | D15: 5439.86 | E15: 3882.3 | F15: 3832.83 | G15: 2628.19
B16: Purchase Of Stock-In Trade | C16: 31.84 | D16: 39.89 | E16: 56.15 | F16: 49.11 | G16: 28.89 | J16: Earnings before Interest and Tax (EBIT) | K16: =(K12-K14) -> 11326.94 | L16: =(L12-L14) -> 8820.88 | M16: =(M12-M14) -> 5705.14 | O16: Earnings before Interest and Tax (EBIT) | P16: =K16/K5 -> 0.16907857 | Q16: =L16/L5 -> 0.13941136 | R16: =M16/M5 -> 0.10089182 | T16: Earnings before Interest and Tax (EBIT) | U16: =(K16-L16)/L16 -> 0.28410544 | V16: =(L16-M16)/M16 -> 0.54612858
B17: Cost of Power Purchased | C17: 20523.61 | D17: 20014.46 | E17: 19062.67 | F17: 14640.62 | G17: 8334.41
B18: Cost Of Fuel | C18: 13918.47 | D18: 14130.47 | E18: 13763.59 | F18: 8290.92 | G18: 9074.96 | J18: Interest expenses (finance costs) | K18: =C22 -> 4702.44 | L18: =D22 -> 4633.22 | M18: =E22 -> 4371.65 | O18: Interest expenses (finance costs) | P18: =K18/K5 -> 0.070193875 | Q18: =L18/L5 -> 0.07322665 | R18: =M18/M5 -> 0.077309889 | T18: Interest expenses (finance costs) | U18: =(K18-L18)/L18 -> 0.014939934 | V18: =(L18-M18)/M18 -> 0.059833244
B19: Operating And Direct Expenses | C19: 1277.81 | D19: 1168.69 | E19: 1194.95 | F19: 1018.19 | G19: 504.6
B20: Changes In Inventories Of FG,WIP And Stock-In Trade | C20: -440.76 | D20: -51.78 | E20: 43.53 | F20: -199.22 | G20: 0.41 | J20: Total Expenses | K20: =C25 -> 60367.67 | L20: =D25 -> 59084.66 | M20: =E25 -> 55213.61 | O20: Total Expenses | P20: =K20/K5 -> 0.90111531 | Q20: =L20/L5 -> 0.93381529 | R20: =M20/M5 -> 0.97641807 | T20: Total Expenses | U20: =(K20-L20)/L20 -> 0.021714773 | V20: =(L20-M20)/M20 -> 0.070110431
B21: Employee Benefit Expenses | C21: 4372.92 | D21: 4036.09 | E21: 3624.26 | F21: 3611.63 | G21: 2156.48 | J21: Earnings before Taxes and exceptional cases | K21: 5526.29 | L21: 4554.45 | M21: 2257.54 | O21: Earnings before Taxes and exceptional cases | P21: =K21/K5 -> 0.082491581 | Q21: =L21/L5 -> 0.071981713 | R21: =M21/M5 -> 0.039923179 | T21: Earnings before Taxes and exceptional cases | U21: =(K21-L21)/L21 -> 0.21338252 | V21: =(L21-M21)/M21 -> 1.0174393
B22: Finance Costs | C22: 4702.44 | D22: 4633.22 | E22: 4371.65 | F22: 3859.02 | G22: 4010.39
B23: Depreciation And Amortisation Expenses | C23: 4116.86 | D23: 3786.37 | E23: 3439.2 | F23: 3122.2 | G23: 2744.94 | J23: Tax Expenses: | O23: Tax Expenses: | T23: Tax Expenses:
B24: Other Expenses | C24: 6943.02 | D24: 5887.39 | E24: 5775.31 | F24: 4060.42 | G24: 2812.48 | J24: Current Tax | K24: 667.37 | L24: 871.47 | M24: 804.33 | O24: Current Tax | P24: =K24/K5 -> 0.0099619105 | Q24: =L24/L5 -> 0.013773321 | R24: =M24/M5 -> 0.014224072 | T24: Current Tax | U24: =(K24-L24)/L24 -> -0.23420198 | V24: =(L24-M24)/M24 -> 0.083473201
B25: Total Expenses | C25: 60367.67 | D25: 59084.66 | E25: 55213.61 | F25: 42285.72 | G25: 32295.75 | J25: Deferred Tax | K25: 567.05 | L25: 725.85 | M25: 1010.3 | O25: Deferred Tax Credit | P25: =K25/K5 -> 0.008464422 | Q25: =L25/L5 -> 0.011471841 | R25: =M25/M5 -> 0.017866522 | T25: Deferred Tax Credit | U25: =(K25-L25)/L25 -> -0.21877798 | V25: =(L25-M25)/M25 -> -0.28155003
B26: Profit/Loss Before Exceptional, ExtraOrdinary Items And Tax | C26: 6624.5 | D26: 4187.66 | E26: 1333.49 | F26: 1449.91 | G26: 611.59 | J26: Tax For Earlier Years | K26: 309.83 | L26: -145.4 | M26: -167.3 | O26: Tax For Earlier Years | P26: =K26/K5 -> 0.0046248688 | Q26: =L26/L5 -> -0.0022980033 | R26: =M26/M5 -> -0.0029585956 | T26: Total For Earlier Years | U26: =(K26-L26)/L26 -> -3.1308803 | V26: =(L26-M26)/M26 -> -0.13090257
B27: Exceptional Items | C27: -1098.21 | D27: 366.79 | E27: 924.05 | F27: -389.74 | G27: 501.75 | J27: Total Tax Expenses | K27: 1544.25 | L27: 1451.92 | M27: 1647.33 | O27: Total Tax Expenses | P27: =K27/K5 -> 0.023051201 | Q27: =L27/L5 -> 0.022947159 | R27: =M27/M5 -> 0.029131998 | T27: Total Tax Expenses | U27: =(K27-L27)/L27 -> 0.063591658 | V27: =(L27-M27)/M27 -> -0.11862226
B28: Profit/Loss Before Tax | C28: 5526.29 | D28: 4554.45 | E28: 2257.54 | F28: 1060.17 | G28: 1113.34 | J28: Profit for the year | K28: =(K21-K27) -> 3982.04 | L28: =(L21-L27) -> 3102.53 | M28: =(M21-M27) -> 610.21 | O28: Profit for the year | P28: =K28/K5 -> 0.059440379 | Q28: =L28/L5 -> 0.049034554 | R28: =M28/M5 -> 0.010791181 | T28: Profit for the year | U28: =(K28-L28)/L28 -> 0.28348155 | V28: =(L28-M28)/M28 -> 4.0843644
B29: Tax Expenses-Continued Operations
B30: Current Tax | C30: 667.37 | D30: 871.47 | E30: 804.33 | F30: 580.3 | G30: 647.57
B31: Deferred Tax | C31: 567.05 | D31: 725.85 | E31: 1010.3 | F31: 492.93 | G31: -145.69
B32: Tax For Earlier Years | C32: 309.83 | D32: -145.4 | E32: -167.3 | F32: -693.67 | G32: 0
B33: Total Tax Expenses | C33: 1544.25 | D33: 1451.92 | E33: 1647.33 | F33: 379.56 | G33: 501.88
B34: Profit/Loss After Tax And Before ExtraOrdinary Items | C34: 3982.04 | D34: 3102.53 | E34: 610.21 | F34: 680.61 | G34: 611.46
B35: Profit/Loss From Continuing Operations | C35: 3982.04 | D35: 3102.53 | E35: 610.21 | F35: 680.61 | G35: 611.46
B36: Profit Loss From Discontinuing Operations | C36: 0 | D36: 0 | E36: 0 | F36: -467.83 | G36: -219.85
B37: Total Tax Expenses Discontinuing Operations | C37: 0 | D37: 0 | E37: 0 | F37: 0 | G37: -173.65
B38: Net Profit Loss From Discontinuing Operations | C38: 0 | D38: 0 | E38: 0 | F38: -467.83 | G38: -46.2
B39: Profit/Loss For The Period | C39: 3982.04 | D39: 3102.53 | E39: 610.21 | F39: 212.78 | G39: 565.26
B40: Minority Interest | C40: -804.37 | D40: -583.85 | E40: -473.23 | F40: -414.15 | G40: -311.27
B41: Share Of Profit/Loss Of Associates | C41: 793.33 | D41: 1177.57 | E41: 3199.46 | F41: 1942.83 | G41: 873.39
...

Sheet Tata Power FCFF and FCFE
A2: Free Cash Flow to Firm
A4: Particulars | C4: 45746 | D4: 45745 | E4: 45744 | F4: 45743 | G4: 45742 | H4: 45741 | I4: 45740 | J4: 45739
A6: Net Income | C6: ='Income Statement'!C73 -> 4461.8105 | D6: ='Income Statement'!D73 -> 4294.6923 | E6: ='Income Statement'!E73 -> 4119.4356 | F6: ='Income Statement'!F73 -> 3939.1118 | G6: ='Income Statement'!G73 -> 3546.4858 | H6: ='Income Statement'!K28 -> 3982.04 | I6: ='Income Statement'!L28 -> 3102.53 | J6: ='Income Statement'!M28 -> 610.21
A7: Depreciation | C7: ='Income Statement'!C67 -> 5714.0705 | D7: ='Income Statement'!D67 -> 5247.7492 | E7: ='Income Statement'!E67 -> 4819.484 | F7: ='Income Statement'!F67 -> 4426.1693 | G7: ='Income Statement'!G67 -> 4334.882 | H7: ='Income Statement'!K14 -> 4116.86 | I7: ='Income Statement'!L14 -> 3786.37 | J7: ='Income Statement'!M14 -> 3439.2
A8: Interest Expense(1-T) | C8: ='Income Statement'!C68*(1-'Income Statement'!H59) -> 6809.9463 | D8: ='Income Statement'!D68*(1-'Income Statement'!H59) -> 6057.1843 | E8: ='Income Statement'!E68*(1-'Income Statement'!H59) -> 5387.6315 | F8: ='Income Statement'!F68*(1-'Income Statement'!H59) -> 4792.0902 | G8: ='Income Statement'!G68*(1-'Income Statement'!H59) -> 4262.3792 | H8: ='Income Statement'!K18*(1-'Income Statement'!H59) -> 3654.7465 | I8: ='Income Statement'!L18*(1-'Income Statement'!H59) -> 3600.9486 | J8: ='Income Statement'!M18*(1-'Income Statement'!H59) -> 3397.6558
A9: Change in Working Capital | C9: ='Balance Sheet'!C73 -> -843.32757 | D9: ='Balance Sheet'!D73 -> -774.50419 | E9: ='Balance Sheet'!E73 -> -711.29744 | F9: ='Balance Sheet'!F73 -> -653.24895 | G9: ='Balance Sheet'!G73 -> 1117.3497 | H9: ='Balance Sheet'!L50 -> -3253.64 | I9: ='Balance Sheet'!M50 -> 599.62
A10: CAPEX | C10: ='Balance Sheet'!C71-'Balance Sheet'!D71+'Income Statement'!C67 -> 14540.216 | D10: ='Balance Sheet'!D71-'Balance Sheet'!E71+'Income Statement'!D67 -> 13353.599 | E10: ='Balance Sheet'!E71-'Balance Sheet'!F71+'Income Statement'!E67 -> 12263.821 | F10: ='Balance Sheet'!F71-'Balance Sheet'!G71+'Income Statement'!F67 -> 11262.979 | G10: ='Balance Sheet'!G71-'Balance Sheet'!H71+'Income Statement'!G67 -> 5921.6867 | H10: ='Balance Sheet'!L28-'Balance Sheet'!M28+'Income Statement'!K14 -> 15475.32 | I10: ='Balance Sheet'!M28-'Balance Sheet'!N28+'Income Statement'!L14 -> 9272.17
A12: FCFF | C12: =C6+C7+C8-C9-C10 -> 3288.9388 | D12: =D6+D7+D8-D9-D10 -> 3020.5308 | E12: =E6+E7+E8-E9-E10 -> 2774.0274 | F12: =F6+F7+F8-F9-F10 -> 2547.641 | G12: =G6+G7+G8-G9-G10 -> 5104.7107 | H12: =H6+H7+H8-H9-H10 -> -468.03349 | I12: =I6+I7+I8-I9-I10 -> 618.05858
A15: Free Cash Flow to Equity
A17: Particulars | C17: 45746 | D17: 45745 | E17: 45744 | F17: 45743 | G17: 45742 | H17: 45741 | I17: 45740 | J17: 45739
A19: Net Income | C19: ='Income Statement'!C73 -> 4461.8105 | D19: ='Income Statement'!D73 -> 4294.6923 | E19: ='Income Statement'!E73 -> 4119.4356 | F19: ='Income Statement'!F73 -> 3939.1118 | G19: ='Income Statement'!G73 -> 3546.4858 | H19: ='Income Statement'!K28 -> 3982.04 | I19: ='Income Statement'!L28 -> 3102.53 | J19: ='Income Statement'!M28 -> 610.21
A20: Depreciation | C20: ='Income Statement'!C67 -> 5714.0705 | D20: ='Income Statement'!D67 -> 5247.7492 | E20: ='Income Statement'!E67 -> 4819.484 | F20: ='Income Statement'!F67 -> 4426.1693 | G20: ='Income Statement'!G67 -> 4334.882 | H20: ='Income Statement'!K14 -> 4116.86 | I20: ='Income Statement'!L14 -> 3786.37 | J20: ='Income Statement'!M14 -> 3439.2
A21: Change in Working Capital | C21: =C9 -> -843.32757 | D21: =D9 -> -774.50419 | E21: =E9 -> -711.29744 | F21: =F9 -> -653.24895 | G21: =G9 -> 1117.3497 | H21: =H9 -> -3253.64 | I21: =I9 -> 599.62
A22: CAPEX | C22: =C10 -> 14540.216 | D22: =D10 -> 13353.599 | E22: =E10 -> 12263.821 | F22: =F10 -> 11262.979 | G22: =G10 -> 5921.6867 | H22: =H10 -> 15475.32 | I22: =I10 -> 9272.17
A23: NP - P = Change in LT Borrowings | C23: ='Balance Sheet'!C74 - 'Balance Sheet'!D74 -> 8762.1299 | D23: ='Balance Sheet'!D74-'Balance Sheet'!E74 -> 7793.5762 | E23: ='Balance Sheet'!E74-'Balance Sheet'!F74 -> 6932.0851 | F23: ='Balance Sheet'!F74-'Balance Sheet'!G74 -> 6165.822 | G23: ='Balance Sheet'!G74-'Balance Sheet'!H74 -> 5484.2606 | H23: ='Balance Sheet'!L11-'Balance Sheet'!M11 -> 6737.47 | I23: ='Balance Sheet'!M11-'Balance Sheet'!N11 -> 6683.76
A25: FCFE | C25: =C19+C20-C21-C22+C23 -> 5241.1225 | D25: =D19+D20-D21-D22+D23 -> 4756.9228 | E25: =E19+E20-E21-E22+E23 -> 4318.481 | F25: =F19+F20-F21-F22+F23 -> 3921.3728 | G25: =G19+G20-G21-G22+G23 -> 6326.5921 | H25: =H19+H20-H21-H22+H23 -> 2614.69 | I25: =I19+I20-I21-I22+I23 -> 3700.87

Sheet Cost of Equity
A1: The Tata Power Company Regression | M1: Date | N1: Close | O1: Open | Q1: Returns (%)
A2: SUMMARY OUTPUT | M2: 44652 | N2: 9324.35 | O2: 9207 | Q2: =(N2-O2)/O2 -> 0.012745737
M3: 44655 | N3: 9514.7 | O3: 9324.35 | Q3: =(N3-O3)/O3 -> 0.020414292
A4: Regression Statistics | M4: 44656 | N4: 9504.95 | O4: 9514.7 | Q4: =(N4-O4)/O4 -> -0.0010247302
A5: Multiple R | B5: 0.654338 | M5: 44657 | N5: 9458.55 | O5: 9504.95 | Q5: =(N5-O5)/O5 -> -0.0048816669
A6: R Square | B6: 0.428158 | M6: 44658 | N6: 9375.65 | O6: 9458.55 | Q6: =(N6-O6)/O6 -> -0.0087645569
A7: Adjusted R Square | B7: 0.427386 | M7: 44659 | N7: 9464.3 | O7: 9375.65 | Q7: =(N7-O7)/O7 -> 0.0094553444
A8: Standard Error | B8: 0.014979 | M8: 44662 | N8: 9446.85 | O8: 9464.3 | Q8: =(N8-O8)/O8 -> -0.0018437708
A9: Observations | B9: 742 | M9: 44663 | N9: 9351.7 | O9: 9446.85 | Q9: =(N9-O9)/O9 -> -0.01007214
M10: 44664 | N10: 9332.25 | O10: 9351.7 | Q10: =(N10-O10)/O10 -> -0.0020798358
A11: ANOVA | M11: 44669 | N11: 9197.35 | O11: 9332.25 | Q11: =(N11-O11)/O11 -> -0.014455249
B12: df | C12: SS | D12: MS | E12: F | F12: Significance F | M12: 44670 | N12: 9073.6 | O12: 9197.35 | Q12: =(N12-O12)/O12 -> -0.013454963
A13: Regression | B13: 1 | C13: 0.124321 | D13: 0.124321 | E13: 554.0648 | F13: 6.96e-92 | M13: 44671 | N13: 9157.95 | O13: 9073.6 | Q13: =(N13-O13)/O13 -> 0.0092962
A14: Residual | B14: 740 | C14: 0.166041 | D14: 0.000224 | M14: 44672 | N14: 9285.85 | O14: 9157.95 | Q14: =(N14-O14)/O14 -> 0.013966008
A15: Total | B15: 741 | C15: 0.290361 | M15: 44673 | N15: 9179.5 | O15: 9285.85 | Q15: =(N15-O15)/O15 -> -0.01145291
M16: 44676 | N16: 9046.5 | O16: 9179.5 | Q16: =(N16-O16)/O16 -> -0.014488807
B17: Coefficients | C17: Standard Error | D17: t Stat | E17: P-value | F17: Lower 95% | G17: Upper 95% | H17: Lower 95.0% | I17: Upper 95.0% | M17: 44677 | N17: 9191.8 | O17: 9046.5 | Q17: =(N17-O17)/O17 -> 0.01606146
A18: Intercept | B18: 4.41e-05 | C18: 0.000551 | D18: 0.080052 | E18: 0.936217 | F18: -0.00104 | G18: 0.001125 | H18: -0.00104 | I18: 0.001125 | M18: 44678 | N18: 9100.05 | O18: 9191.8 | Q18: =(N18-O18)/O18 -> -0.0099817228
A19: 0.0127 | B19: 1.501188 | C19: 0.063776 | D19: 23.53858 | E19: 6.96e-92 | F19: 1.375985 | G19: 1.626391 | H19: 1.375985 | I19: 1.626391 | M19: 44679 | N19: 9205.35 | O19: 9100.05 | Q19: =(N19-O19)/O19 -> 0.011571365
M20: 44680 | N20: 9123.4 | O20: 9205.35 | Q20: =(N20-O20)/O20 -> -0.0089024317
M21: 44683 | N21: 9098.95 | O21: 9123.4 | Q21: =(N21-O21)/O21 -> -0.002679922
A22: Beta Equity | B22: =B19 -> 1.501188 | M22: 44685 | N22: 8885.25 | O22: 9098.95 | Q22: =(N22-O22)/O22 -> -0.023486226
M23: 44686 | N23: 8892.15 | O23: 8885.25 | Q23: =(N23-O23)/O23 -> 0.00077656791
A24: Average Market Returns | B24: =AVERAGE(Q2:Q744) -> 0.00050000597 | M24: 44687 | N24: 8740.95 | O24: 8892.15 | Q24: =(N24-O24)/O24 -> -0.017003762
M25: 44690 | N25: 8652.95 | O25: 8740.95 | Q25: =(N25-O25)/O25 -> -0.010067556
A26: Annualized Market Return(Rm) | B26: =POWER(1+B24,252)-1 -> 0.13424816 | M26: 44691 | N26: 8578.8 | O26: 8652.95 | Q26: =(N26-O26)/O26 -> -0.0085693318
M27: 44692 | N27: 8544.7 | O27: 8578.8 | Q27: =(N27-O27)/O27 -> -0.0039749149
A28: Risk Free Rate(Rf) | B28: 0.0654 | C28: https://in.investing.com/rates-bonds/india-10-year-bond-yield-historical-data | M28: 44693 | N28: 8348.4 | O28: 8544.7 | Q28: =(N28-O28)/O28 -> -0.022973305
M29: 44694 | N29: 8343.1 | O29: 8348.4 | Q29: =(N29-O29)/O29 -> -0.00063485219
A30: Cost of Equity Capital | M30: 44697 | N30: 8399.05 | O30: 8343.1 | Q30: =(N30-O30)/O30 -> 0.0067061404
A31: Re = Rf + β(Rm-Rf) | B31: =B28+(B22*(B26-B28)) -> 0.16875403 | M31: 44698 | N31: 8619.55 | O31: 8399.05 | Q31: =(N31-O31)/O31 -> 0.026252969
M32: 44699 | N32: 8611.25 | O32: 8619.55 | Q32: =(N32-O32)/O32 -> -0.0009629273
M33: 44700 | N33: 8378.35 | O33: 8611.25 | Q33: =(N33-O33)/O33 -> -0.027046015
M34: 44701 | N34: 8597.1 | O34: 8378.35 | Q34: =(N34-O34)/O34 -> 0.026108959
M35: 44704 | N35: 8562.85 | O35: 8597.1 | Q35: =(N35-O35)/O35 -> -0.0039839015
M36: 44705 | N36: 8511.35 | O36: 8562.85 | Q36: =(N36-O36)/O36 -> -0.0060143527
M37: 44706 | N37: 8426.55 | O37: 8511.35 | Q37: =(N37-O37)/O37 -> -0.0099631668
M38: 44707 | N38: 8511.5 | O38: 8426.55 | Q38: =(N38-O38)/O38 -> 0.010081231
M39: 44708 | N39: 8606.15 | O39: 8511.5 | Q39: =(N39-O39)/O39 -> 0.011120249
M40: 44711 | N40: 8779.1 | O40: 8606.15 | Q40: =(N40-O40)/O40 -> 0.020096094
...

Sheet WACC Calculation
A4: Cost of Debt
A5: Interest Coverage Ratio(24-25) | B5: ='Income Statement'!K16/'Income Statement'!K18 -> 2.4087367
A6: Default Spread | B6: 0.0075
A7: Risk Free Rate | B7: 0.06536
A8: Cost of Debt | B8: =B7+B6 -> 0.07286
A11: Market Value of Equity
A12: Share Price Mar 2025 | B12: 379.6
A13: Share Outstanding | B13: 3201993958
A14: Market Value of Equity | B14: =B12*B13/POWER(10,7) -> 121547.69 | C14: crores
A16: Market Value of Debt
A17: Book Value of Debt | B17: ='Balance Sheet'!L11 -> 44129.72
A18: Maturity | B18: 5
A19: Interest Expense | B19: ='Income Statement'!K18 -> 4702.44
A20: Cost of Debt | B20: 0.0729
A21: Market Value of Debt | B21: =B19*((1-1/((1+B20)^B18))/B20)+(B17/((1+B20)^B18)) -> 50173.085
A24: WACC
A25: Enterprise Value | B25: =B14+B21 -> 171720.78
A26: D/V | B26: =B21/B25 -> 0.29217831
A27: E/V | B27: =B14/B25 -> 0.70782169
A28: Tax Rate | B28: ='Income Statement'!H59 -> 0.22279784
A29: Cost of Capital | B29: =B27*('Cost of Equity'!B31)+'WACC Calculation'!B26*('WACC Calculation'!B8)*(1-'WACC Calculation'!B28) -> 0.13599293

Sheet Growth and DCF Valuation
A1: Ratios Required | B1: 45741 | C1: 45740 | D1: 45739
A2: Net Income | B2: ='Income Statement'!K28 -> 3982.04 | C2: ='Income Statement'!L28 -> 3102.53 | D2: ='Income Statement'!M28 -> 610.21
A3: Total Assets | B3: ='Balance Sheet'!L48 -> 156698.95 | C3: ='Balance Sheet'!M48 -> 139542.35 | D3: ='Balance Sheet'!N48 -> 128337.49
A4: Total shareholders equity | B4: ='Balance Sheet'!L8 -> 35840.67 | C4: ='Balance Sheet'!M8 -> 32355.29 | D4: ='Balance Sheet'!N8 -> 28787.43
A5: Dividend per share | B5: 2 | C5: 2 | D5: 1.75
A6: Dividends Paid | B6: ='WACC Calculation'!$B$13*'Growth and DCF Valuation'!B5/POWER(10,7) -> 640.39879 | C6: ='WACC Calculation'!$B$13*'Growth and DCF Valuation'!C5/POWER(10,7) -> 640.39879 | D6: ='WACC Calculation'!$B$13*'Growth and DCF Valuation'!D5/POWER(10,7) -> 560.34894 | E6: in crores
A7: Payout Ratio | B7: =B6/B2 -> 0.16082179 | C7: =C6/C2 -> 0.2064118 | D7: =D6/D2 -> 0.91828869
A8: Retention ratio | B8: =1-B7 -> 0.83917821 | C8: =1-C7 -> 0.7935882 | D8: =1-D7 -> 0.081711308
A9: ROA | B9: =B2/B3 -> 0.02541204 | C9: =C2/C3 -> 0.022233609 | D9: =D2/D3 -> 0.0047547291
A10: ROE | B10: =B2/B4 -> 0.11110395 | C10: =C2/C4 -> 0.09588942 | D10: =D2/D4 -> 0.021197099
A13: Terminal Growth rate using reinvestment rate and ROA capital
A14: ROA | B14: =AVERAGE(B9:D9) -> 0.017466793
A15: Reinvestment rate | B15: =AVERAGE(B8:D8) -> 0.57149257
A16: g | B16: =B14*B15 -> 0.0099821423
A17: Cost of Capital | B17: ='WACC Calculation'!B29 -> 0.13599293
A18: FCFF in 2030 | B18: ='Tata Power FCFF and FCFE'!C12 -> 3288.9388
A19: Terminal value at end of 2030 | B19: =B18*((1+B16)/(B17-B16)) -> 26360.993
A20: Terminal value at end of 2025 | B20: =B19/(1+B17)^5 -> 13934.251
A22: Terminal Growth rate using reinvestment rate and ROE capital
A23: ROE | B23: =AVERAGE(B10:D10) -> 0.07606349
A24: Reinvestment rate | B24: =AVERAGE(B8:D8) -> 0.57149257
A25: g | B25: =B23*B24 -> 0.04346972
A26: Cost of Capital | B26: ='WACC Calculation'!B29 -> 0.13599293
A27: FCFE in 2030 | B27: ='Tata Power FCFF and FCFE'!C25 -> 5241.1225
A28: Terminal value at end of 2030 | B28: =B27*((1+B25)/(B26-B25)) -> 59108.981
A29: Terminal value at end of 2025 | B29: =B28/(1+B26)^5 -> 31244.626
B31: 45742 | C31: 45743 | D31: 45744 | E31: 45745 | F31: 45746 | G31: PV of Terminal Value
A32: FCFF | B32: ='Tata Power FCFF and FCFE'!G12 -> 5104.7107 | C32: ='Tata Power FCFF and FCFE'!F12 -> 2547.641 | D32: ='Tata Power FCFF and FCFE'!E12 -> 2774.0274 | E32: ='Tata Power FCFF and FCFE'!D12 -> 3020.5308 | F32: ='Tata Power FCFF and FCFE'!C12 -> 3288.9388 | G32: =B20 -> 13934.251
A34: NPV | B34: {=(NPV(B17,B32:F32)+G32)} -> 25846.593
B36: 45742 | C36: 45743 | D36: 45744 | E36: 45745 | F36: 45746 | G36: PV of Terminal Value
A37: FCFE | B37: ='Tata Power FCFF and FCFE'!G25 -> 6326.5921 | C37: ='Tata Power FCFF and FCFE'!F25 -> 3921.3728 | D37: ='Tata Power FCFF and FCFE'!E25 -> 4318.481 | E37: ='Tata Power FCFF and FCFE'!D25 -> 4756.9228 | F37: ='Tata Power FCFF and FCFE'!C25 -> 5241.1225 | G37: =B29 -> 31244.626
A39: NPV | B39: {=NPV(B26,B37:F37)+G37} -> 48425.197

Sheet Relative Valuation
A1: Relative Valuation of TATA POWER LTD.
B3: Target Company | C3: Comparable Companies
A4: Ratios | B4: TATA POWER | C4: ADANI POWER | D4: CESC | E4: TORRENT POWER
A5: P/E Ratio | B5: 30.6 | C5: 23.9 | D5: 15.7 | E5: 21.77
A6: EV/EBITDA | B6: 16.98 | C6: 17.82 | D6: 12.06 | E6: 13.2
A7: EPS | B7: 12.41 | C7: 6.25 | D7: 10.33 | E7: 21.03
A9: Industry EV/EBITDA Ratio | B9: =AVERAGE(C6:E6) -> 14.36
A10: Industry P/E Ratio | B10: =AVERAGE(C5:E5) -> 20.456667 | E10: Through relative valuation we get that that the earnings per share for TATA POWER is lower than the industry average hence currently it is overpriced.
A12: TATA POWER EBITDA | B12: ='Income Statement'!C28 -> 5526.29 | C12: CRORES
A13: TATA POWER EPS | B13: =B7 -> 12.41
A15: TATA POWER EV | B15: =B9*B12 -> 79357.524 | C15: CRORES
A16: TATA POWER MVE | B16: =B10*B13 -> 253.86723 | C16: CRORES
